# Panic 과 Recover

- Go에서 Error을 이용하여 문제 상황을 처리할 수 있다. 
- 에러를 이용하여 문제 상황을 처리하는 방법도 있으나, 문제 상황이 되면 시스템을 종료 시켜야 하는 경우도 있다. 
- 이런 경우 panic을 이용하면, 문제에 대해서 프로그램을 종료할 수 있다. 
- panic은 프로그램을 종요하지만, 필요한 경우에는 panic 상황에서 다시 제어를 복구하고, 프로그램을 게속 실행해야하는 상황도 발생한다. 
- 이 경우 recover를 이용하면 panic 상황을 복구할 수 있다. 

## Use Case

- panic, recover 을 사용하는 방식보다 error을 가능하면 사용하는 것이 좋다. 
- 구분
  - error: 
    - 일반적인 오류 처리
  - panic, recover:
    - 회복할 수 없는 오류가 발생한경우 사용 
    - 프로그래머 오류 필수 아규먼트가 널인경우 더이상 프로그램 수행 불가인경우 

## Panic 이용하기 

- panic 함수는 다음과 같은 형태로 사용할 수 있다. 

```go
func panic(interface{})
```

```go
package main

import "fmt"

func greeting(username *string) {
	if username == nil {
		panic("username cannot be nil")
	}

	fmt.Println(*username, "Nice meet U")
}

func main() {
	name := "Kido"
	greeting(&name)
	greeting(nil)

	fmt.Println("Program -------- exit ----------")
}
```

- 위 실행 결과는 다음과 같다. 

```go
Kido Nice meet U
panic: username cannot be nil

goroutine 1 [running]:
main.greeting(0x0?)
        /Users/1111489/Documents/03.TUTORIALS/GO/go-tutorials/17_Deper_ErrorHandling/04_panic_basic.go:7 +0x9c
main.main()
        /Users/1111489/Documents/03.TUTORIALS/GO/go-tutorials/17_Deper_ErrorHandling/04_panic_basic.go:16 +0x40
exit status 2
```

- 파라미터로 name에 대한 포인터를 전달한다. 
- 정상적인 케이스는 우리가 원하는 값인 'Kido Nice meet U' 를 출력했다. 
- 그러나 nil이 전달된경우 panic이 발생하고, 해당 패닉이 발생한 지점에 대한 오류 코드가 출력이 됨을 확인할 수 있다. 

## go 내장된 panic 오류에 대한 샘플

- go에서 프로그램 오류로 인해서 panic이 발생하는 케이스를 알아보자. 

```go
package main

import "fmt"

func printSlice(paramSlice []int, number int) int {
	return paramSlice[number]
}

func main() {
	sl := []int{1, 2, 3, 4}
	fmt.Println("Result Value: ", printSlice(sl, 10))
}

```

- 위 코드 수행결과는 다음과 같다. 

```go
panic: runtime error: index out of range [10] with length 4

goroutine 1 [running]:
main.printSlice(...)
        /Users/1111489/Documents/03.TUTORIALS/GO/go-tutorials/17_Deper_ErrorHandling/04_panic_builtin.go:6
main.main()
        /Users/1111489/Documents/03.TUTORIALS/GO/go-tutorials/17_Deper_ErrorHandling/04_panic_builtin.go:11 +0x28
exit status 2
```

## Defer 를 이용한 panic 이후 처리 수행하기 

- defer는 특정 메소드가 리턴하기 전에 수행되도록 실행을 연기한다. 
- panic이 발생하는 경우 defer 역시 defer를 수행하고, 프로그램을 종료하게 된다. 

```go
package main

import "fmt"

func greeting(username *string) {
	defer fmt.Println("----- greeting end ----")
	if username == nil {
		panic("username cannot be nil")
	}

	fmt.Println(*username, "Nice meet U")
}

func main() {
	defer fmt.Println("---- end of main ----")
	greeting(nil)

	fmt.Println("Program -------- exit ----------")
}
```

- 위 실행결과는 다음과 같다. 

```go
----- greeting end ----
---- end of main ----
panic: username cannot be nil

goroutine 1 [running]:
main.greeting(0x102248880?)
        /Users/1111489/Documents/03.TUTORIALS/GO/go-tutorials/17_Deper_ErrorHandling/04_panic_defer.go:8 +0xec
main.main()
        /Users/1111489/Documents/03.TUTORIALS/GO/go-tutorials/17_Deper_ErrorHandling/04_panic_defer.go:16 +0x68
exit status 2
```

- nil이 파라미터로 전달된경우, panic을 발생 시킨다. 
- 그러나 greeting 메소드는 derer를 이용하여 함수 종료시 수행되도록 작업이 수행되어 있다. 
- 메인 메소드역시 panic으로 시스템을 종료하기 전에 defer를 수행할 수 있다. 

## Recover 로 panic 복구하기

- recover은 내장 함수이며, 패닉 프로그램의 컨트롤을 다시 획득하여 프로그램을 진행하기 위한 방법을 제공한다. 

```go
func recover() interface{}
```

- recover는 defer 함수 내에서 호출될 때문 유용하다. (이 부분은 매우 중요한 포인트이다.)
- 지연된 함수 내에서 복구 호출을 실행하면 정상적인 실행을 복원하여 패닉 시퀀스를 중지하고 패닉 함수 호출에 전달된 오류 메시지를 검색한다. 
- 만약 지연된 함수 외부에서 복구가 호출되면 패닉 시퀀스를 중지하지 않는다.

```go
package main

import "fmt"

func recoverUserName() {
	if r := recover(); r != nil {
		fmt.Println("Recover :", r)
	}
}

func greeting(username *string) {
	defer recoverUserName()
	if username == nil {
		panic("username cannot be nil")
	}

	fmt.Println(*username, "Nice meet U")
}

func main() {
	defer fmt.Println("---- end of main ----")
	greeting(nil)

	fmt.Println("Program -------- exit ----------")
}

```

- 위 실행 결과는 다음과 같다. 

```go
Recover : username cannot be nil
Program -------- exit ----------
---- end of main ----
```

- 위 코드에서와 같이 recoverUserName() 메소드를 지정하였다. 
- recover() 메소드는 현재 defer 내부에서 발생한 패닉 정보를 복구한다. 그러므로 recover 결과를 출력한다. 
- defer recoverUserName() 메소드를 greeting메소드에서 호출하여 패닉 발생한경우 defer내에서 수행될 수 있도록 하였다. 
- panic으로 프로그램이 바로 종요하지 않고, 복구되고 다음 부분을 실행하게 된다. 

## recover를 수행할때 stack trace로 관련 오류 구체적으로 확인하기

- recover를 수행할때 Stack의 내용을 화면에 출력할 수 있다. 

```go
package main

import (
	"fmt"
	"runtime/debug"
)

func recoverUserName() {
	if r := recover(); r != nil {
		fmt.Println("Recover :", r)
		debug.PrintStack()
	}
}

func greeting(username *string) {
	defer recoverUserName()
	if username == nil {
		panic("username cannot be nil")
	}

	fmt.Println(*username, "Nice meet U")
}

func main() {
	defer fmt.Println("---- end of main ----")
	greeting(nil)

	fmt.Println("Program -------- exit ----------")
}

```

- 위 내용에서와 같이 debug.PrintStack() 으로 출력을 하였다. 
- 이는 복구가 완료되고 나서 패닉 원인에 대한 stack를 trace한다. 
- 결과는 다음과 같다. 

```go
Recover : username cannot be nil
goroutine 1 [running]:
runtime/debug.Stack()
        /usr/local/go/src/runtime/debug/stack.go:24 +0x68
runtime/debug.PrintStack()
        /usr/local/go/src/runtime/debug/stack.go:16 +0x20
main.recoverUserName()
        /Users/1111489/Documents/03.TUTORIALS/GO/go-tutorials/17_Deper_ErrorHandling/04_panic_recover_stack_trace.go:11 +0x7c
panic({0x10509b700, 0x1050abca0})
        /usr/local/go/src/runtime/panic.go:838 +0x204
main.greeting(0x105120940?)
        /Users/1111489/Documents/03.TUTORIALS/GO/go-tutorials/17_Deper_ErrorHandling/04_panic_recover_stack_trace.go:18 +0xc0
main.main()
        /Users/1111489/Documents/03.TUTORIALS/GO/go-tutorials/17_Deper_ErrorHandling/04_panic_recover_stack_trace.go:26 +0x68
Program -------- exit ----------
---- end of main ----
```

## go routine 에서 panic 

- go routine 에서 panic이 발생한경우 처리가 불가능하다. 
- 일단 go routine 함수내에서 defer로 panic을 수행하면, 서로다른 go routine이기 때문에 recover 를 수행할 수 없게 된다. 

